<?xml version="1.0"?>
<robot name="new4s" xmlns:xacro="http://ros.org/wiki/xacro">

  <xacro:include filename="/home/lihaoyu/hokuyo/src/erratic_robot/erratic_description/urdf/erratic_hokuyo_laser.xacro" />
  <xacro:property name="body_size" value="0.3 0.2 0.1"/>
  <xacro:property name="wheel_length" value="0.05"/>
  <xacro:property name="wheel_radius" value="0.05"/>
  <xacro:property name="wheel1_pose" value="0.1  0.1  -0.025"/>
  <xacro:property name="wheel2_pose" value="0.1  -0.1 -0.025"/>
  <xacro:property name="wheel3_pose" value="-0.1 0.1  -0.025"/>
  <xacro:property name="wheel4_pose" value="-0.1 -0.1 -0.025"/>
  <xacro:property name="kinect_pose" value="0.125 0    0.06"/>
  
  <xacro:macro name="wheel" params="wheelname position">
    <link name="${wheelname}">
      <visual>
        <geometry>
          <cylinder length="${wheel_length}" radius="${wheel_radius}"/>
        </geometry>
        <material name="black">
          <color rgba="0 0 0 1"/>
        </material>
      </visual>
      <collision>
        <geometry>
          <cylinder length="${wheel_length}" radius="${wheel_radius}"/>
        </geometry>
      </collision>
    </link>

    <joint name="base_to_${wheelname}" type="continuous">
      <parent link="base_link"/>
      <child  link="${wheelname}"/>
      <origin rpy="1.57 0 0" xyz="${position}"/>
      <axis xyz="0 0 1"/>
      <limit effort="30" velocity="10"/>
      <dynamics damping="0.2" friction="0.2"/>
    </joint>
  </xacro:macro>

  <xacro:macro name="camera" params="kine_name kine_postion">

    <joint name="base_to_camera_link" type="fixed">
      <parent link="base_link"/>
      <child  link="camera_link"/>
      <origin rpy="0 0 0" xyz="${kine_postion}"/>
    </joint>

  </xacro:macro>

  <xacro:wheel wheelname="wheel_1" position="${wheel1_pose}"/>
  <xacro:wheel wheelname="wheel_2" position="${wheel2_pose}"/>
  <xacro:wheel wheelname="wheel_3" position="${wheel3_pose}"/>
  <xacro:wheel wheelname="wheel_4" position="${wheel4_pose}"/>
  

  <link name="base_link">
    <visual>
      <geometry>
        <box size="${body_size}"/>
      </geometry>
      <material name="white">
         <color rgba="1 1 0 0.6"/>
      </material>
    </visual>
    <collision>
      <geometry>
        <box size="${body_size}"/>
      </geometry>
    </collision>
  </link>
  
  <erratic_hokuyo_laser parent="base_link">
    <origin xyz="0 0 0.05" rpy="0 0 0" />
  </erratic_hokuyo_laser>

</robot>
