<?xml version="1.0" ?>
<!-- =================================================================================== -->
<!-- |    This document was autogenerated by xacro from new3s.xacro                    | -->
<!-- |    EDITING THIS FILE BY HAND IS NOT RECOMMENDED                                 | -->
<!-- =================================================================================== -->
<robot name="new3s" xmlns:xacro="http://ros.org/wiki/xacro">
  <link name="wheel_1">
    <visual>
      <geometry>
        <cylinder length="0.05" radius="0.05"/>
      </geometry>
      <material name="black">
        <color rgba="0 0 0 1"/>
      </material>
    </visual>
  </link>
  <joint name="base_to_wheel_1" type="continuous">
    <parent link="base_link"/>
    <child link="wheel_1"/>
    <origin rpy="0 1.57 0" xyz="0.1 0.1 -0.025"/>
    <axis xyz="0 0 1"/>
    <limit effort="30" velocity="10"/>
    <dynamics damping="0.2" friction="0.2"/>
  </joint>
  <link name="wheel_2">
    <visual>
      <geometry>
        <cylinder length="0.05" radius="0.05"/>
      </geometry>
      <material name="black">
        <color rgba="0 0 0 1"/>
      </material>
    </visual>
  </link>
  <joint name="base_to_wheel_2" type="continuous">
    <parent link="base_link"/>
    <child link="wheel_2"/>
    <origin rpy="0 1.57 0" xyz="0.1 -0.1 -0.025"/>
    <axis xyz="0 0 1"/>
    <limit effort="30" velocity="10"/>
    <dynamics damping="0.2" friction="0.2"/>
  </joint>
  <link name="wheel_3">
    <visual>
      <geometry>
        <cylinder length="0.05" radius="0.05"/>
      </geometry>
      <material name="black">
        <color rgba="0 0 0 1"/>
      </material>
    </visual>
  </link>
  <joint name="base_to_wheel_3" type="continuous">
    <parent link="base_link"/>
    <child link="wheel_3"/>
    <origin rpy="0 1.57 0" xyz="-0.1 0.1 -0.025"/>
    <axis xyz="0 0 1"/>
    <limit effort="30" velocity="10"/>
    <dynamics damping="0.2" friction="0.2"/>
  </joint>
  <link name="wheel_4">
    <visual>
      <geometry>
        <cylinder length="0.05" radius="0.05"/>
      </geometry>
      <material name="black">
        <color rgba="0 0 0 1"/>
      </material>
    </visual>
  </link>
  <joint name="base_to_wheel_4" type="continuous">
    <parent link="base_link"/>
    <child link="wheel_4"/>
    <origin rpy="0 1.57 0" xyz="-0.1 -0.1 -0.025"/>
    <axis xyz="0 0 1"/>
    <limit effort="30" velocity="10"/>
    <dynamics damping="0.2" friction="0.2"/>
  </joint>
  <link name="base_link">
    <visual>
      <geometry>
        <box size="0.2 0.3 0.1"/>
      </geometry>
      <material name="white">
        <color rgba="1 1 0 0.6"/>
      </material>
    </visual>
  </link>
</robot>

