<?xml version="1.0" ?>
<!-- =================================================================================== -->
<!-- |    This document was autogenerated by xacro from new4s.xacro                    | -->
<!-- |    EDITING THIS FILE BY HAND IS NOT RECOMMENDED                                 | -->
<!-- =================================================================================== -->
<robot name="new4s" xmlns:controller="http://playerstage.sourceforge.net/gazebo/xmlschema/#controller" xmlns:interface="http://playerstage.sourceforge.net/gazebo/xmlschema/#interface" xmlns:sensor="http://playerstage.sourceforge.net/gazebo/xmlschema/#sensor" xmlns:xacro="http://ros.org/wiki/xacro">
  <link name="wheel_1">
    <visual>
      <geometry>
        <cylinder length="0.05" radius="0.05"/>
      </geometry>
      <material name="black">
        <color rgba="0 0 0 1"/>
      </material>
    </visual>
    <collision>
      <geometry>
        <cylinder length="0.05" radius="0.05"/>
      </geometry>
    </collision>
  </link>
  <joint name="base_to_wheel_1" type="continuous">
    <parent link="base_link"/>
    <child link="wheel_1"/>
    <origin rpy="1.57 0 0" xyz="0.1  0.1  -0.025"/>
    <axis xyz="0 0 1"/>
    <limit effort="30" velocity="10"/>
    <dynamics damping="0.2" friction="0.2"/>
  </joint>
  <link name="wheel_2">
    <visual>
      <geometry>
        <cylinder length="0.05" radius="0.05"/>
      </geometry>
      <material name="black">
        <color rgba="0 0 0 1"/>
      </material>
    </visual>
    <collision>
      <geometry>
        <cylinder length="0.05" radius="0.05"/>
      </geometry>
    </collision>
  </link>
  <joint name="base_to_wheel_2" type="continuous">
    <parent link="base_link"/>
    <child link="wheel_2"/>
    <origin rpy="1.57 0 0" xyz="0.1  -0.1 -0.025"/>
    <axis xyz="0 0 1"/>
    <limit effort="30" velocity="10"/>
    <dynamics damping="0.2" friction="0.2"/>
  </joint>
  <link name="wheel_3">
    <visual>
      <geometry>
        <cylinder length="0.05" radius="0.05"/>
      </geometry>
      <material name="black">
        <color rgba="0 0 0 1"/>
      </material>
    </visual>
    <collision>
      <geometry>
        <cylinder length="0.05" radius="0.05"/>
      </geometry>
    </collision>
  </link>
  <joint name="base_to_wheel_3" type="continuous">
    <parent link="base_link"/>
    <child link="wheel_3"/>
    <origin rpy="1.57 0 0" xyz="-0.1 0.1  -0.025"/>
    <axis xyz="0 0 1"/>
    <limit effort="30" velocity="10"/>
    <dynamics damping="0.2" friction="0.2"/>
  </joint>
  <link name="wheel_4">
    <visual>
      <geometry>
        <cylinder length="0.05" radius="0.05"/>
      </geometry>
      <material name="black">
        <color rgba="0 0 0 1"/>
      </material>
    </visual>
    <collision>
      <geometry>
        <cylinder length="0.05" radius="0.05"/>
      </geometry>
    </collision>
  </link>
  <joint name="base_to_wheel_4" type="continuous">
    <parent link="base_link"/>
    <child link="wheel_4"/>
    <origin rpy="1.57 0 0" xyz="-0.1 -0.1 -0.025"/>
    <axis xyz="0 0 1"/>
    <limit effort="30" velocity="10"/>
    <dynamics damping="0.2" friction="0.2"/>
  </joint>
  <link name="base_link">
    <visual>
      <geometry>
        <box size="0.3 0.2 0.1"/>
      </geometry>
      <material name="white">
        <color rgba="1 1 0 0.6"/>
      </material>
    </visual>
    <collision>
      <geometry>
        <box size="0.3 0.2 0.1"/>
      </geometry>
    </collision>
  </link>
  <joint name="laser_base_mount_joint" type="fixed">
    <origin rpy="0 0 0" xyz="0 0 0.05"/>
    <parent link="base_link"/>
    <child link="laser_base_link"/>
  </joint>
  <link name="laser_base_link" type="fixed">
    <inertial>
      <mass value="0.1"/>
      <origin xyz="0 0 0.0"/>
      <inertia ixx="0.1" ixy="0" ixz="0" iyy="0.1" iyz="0" izz="0.1"/>
    </inertial>
    <visual>
      <origin rpy="0 0 0" xyz="0 0 0.025"/>
      <geometry>
        <box size="0.05 0.05 0.05"/>
      </geometry>
    </visual>
    <collision>
      <origin rpy="0 0 0" xyz="0 0 0.025"/>
      <geometry>
        <box size="0.05 0.05 0.05"/>
      </geometry>
    </collision>
  </link>
  <joint name="base_scan_joint" type="fixed">
    <origin rpy="0 0 0" xyz="0 0 0.05"/>
    <parent link="laser_base_link"/>
    <child link="base_scan_link"/>
  </joint>
  <link name="base_scan_link" type="laser">
    <inertial>
      <mass value="0.1"/>
      <origin xyz="0 0 0.0"/>
      <inertia ixx="0.1" ixy="0" ixz="0" iyy="0.1" iyz="0" izz="0.1"/>
    </inertial>
    <visual>
      <origin rpy="0 0 0" xyz="0 0 0.014"/>
      <geometry>
        <cylinder length="0.028" radius="0.0229"/>
      </geometry>
    </visual>
    <collision>
      <origin rpy="0 0 0" xyz="0 0 0.014"/>
      <geometry>
        <cylinder length="0.028" radius="0.0229"/>
      </geometry>
    </collision>
  </link>
  <gazebo reference="base_scan_link">
    <sensor:ray name="laser">
      <rayCount>683</rayCount>
      <rangeCount>683</rangeCount>
      <laserCount>1</laserCount>
      <origin>0.0 0.0 0.0</origin>
      <displayRays>false</displayRays>
      <minAngle>-135</minAngle>
      <maxAngle> 135</maxAngle>
      <minRange>0.06</minRange>
      <maxRange>4.0</maxRange>
      <resRange>0.001</resRange>
      <updateRate>10.0</updateRate>
      <controller:gazebo_ros_laser name="gazebo_ros_base_scan_link_controller" plugin="libgazebo_ros_laser.so">
        <gaussianNoise>0.005</gaussianNoise>
        <alwaysOn>true</alwaysOn>
        <updateRate>10.0</updateRate>
        <topicName>base_scan/scan</topicName>
        <frameName>base_scan_link</frameName>
        <interface:laser name="gazebo_ros_base_scan_link_iface"/>
      </controller:gazebo_ros_laser>
    </sensor:ray>
  </gazebo>
  <gazebo reference="laser_base_link">
    <material>Erratic/Grey</material>
  </gazebo>
  <gazebo reference="base_scan_link">
    <material>Erratic/Black</material>
  </gazebo>
</robot>

